<?xml version="1.0" encoding="utf-8"?>
<!-- This URDF was automatically created by SolidWorks to URDF Exporter! Originally created by Stephen Brawner (brawner@gmail.com) 
     Commit Version: 1.5.1-0-g916b5db  Build Version: 1.5.7152.31018
     For more information, please see http://wiki.ros.org/sw_urdf_exporter -->
<robot
  name="catapult_final">
  <link
    name="base">
    <inertial>
      <origin
        xyz="0 0 0.0375324675324675"
        rpy="0 0 0" />
      <mass
        value="1000" />
      <inertia
        ixx="10"
        ixy="0"
        ixz="0"
        iyy="10"
        iyz="0"
        izz="100" />
    </inertial>
    <visual>
      <origin
        xyz="0 0 0"
        rpy="0 0 0" />
      <geometry>
        <mesh
          filename="package://catapult_final/meshes/base.STL" />
      </geometry>
      <material
        name="">
        <color
          rgba="0.792156862745098 0.819607843137255 0.933333333333333 1" />
      </material>
    </visual>
    <collision>
      <origin
        xyz="0 0 0"
        rpy="0 0 0" />
      <geometry>
        <mesh
          filename="package://catapult_final/meshes/base.STL" />
      </geometry>
    </collision>
  </link>
  <link
    name="rotation">
    <inertial>
      <origin
        xyz="0 1.11022302462516E-16 0.079371564008676"
        rpy="0 0 0" />
      <mass
        value="5" />
      <inertia
        ixx="1"
        ixy="0"
        ixz="0"
        iyy="1"
        iyz="0"
        izz="1" />
    </inertial>
    <visual>
      <origin
        xyz="0 0 0"
        rpy="0 0 0" />
      <geometry>
        <mesh
          filename="package://catapult_final/meshes/rotation.STL" />
      </geometry>
      <material
        name="">
        <color
          rgba="0.792156862745098 0.819607843137255 0.933333333333333 1" />
      </material>
    </visual>
    <collision>
      <origin
        xyz="0 0 0"
        rpy="0 0 0" />
      <geometry>
        <mesh
          filename="package://catapult_final/meshes/rotation.STL" />
      </geometry>
    </collision>
  </link>
  <joint
    name="base_rotate"
    type="revolute">
    <origin
      xyz="0 0 0"
      rpy="0 0 0" />
    <parent
      link="base" />
    <child
      link="rotation" />
    <axis
      xyz="0 0 1" />
    <limit
      lower="-3.14"
      upper="3.14"
      effort="1000"
      velocity="10" />
  </joint>
  <link
    name="bowl">
    <inertial>
      <origin
        xyz="-0.885457329534856 0.167135856366484 0.145562066427354"
        rpy="0 0 0" />
      <mass
        value="0.5" />
      <inertia
        ixx="1.31762941025929"
        ixy="1.80591261327751"
        ixz="-0.085557718174403"
        iyy="10.5441693611195"
        iyz="0.0161495782806831"
        izz="11.4697939499785" />
    </inertial>
    <visual>
      <origin
        xyz="0 0 0"
        rpy="0 0 0" />
      <geometry>
        <mesh
          filename="package://catapult_final/meshes/bowl.STL" />
      </geometry>
      <material
        name="">
        <color
          rgba="0.792156862745098 0.819607843137255 0.933333333333333 1" />
      </material>
    </visual>
    <collision>
      <origin
        xyz="0 0 0"
        rpy="0 0 0" />
      <geometry>
        <mesh
          filename="package://catapult_final/meshes/bowl.STL" />
      </geometry>
    </collision>
  </link>
  <joint
    name="throwing"
    type="revolute">
    <origin
      xyz="0 0 0"
      rpy="0 0 0" />
    <parent
      link="rotation" />
    <child
      link="bowl" />
    <axis
      xyz="0.18548 0.98265 0" />
    <limit
      lower="0"
      upper="0.785"
      effort="1000"
      velocity="10" />
  </joint>


  <transmission name="base_joint" type="SimpleTransmission">
    <type>transmission_interface/SimpleTransmission</type>
    <actuator name="base_motor">
      <mechanicalReduction>1</mechanicalReduction>
    </actuator>
    <joint name="base_rotate">
      <hardwareInterface>hardware_interface/VelocityJointInterface</hardwareInterface>
    </joint>
  </transmission>



  <transmission name="throwing_joint" type="SimpleTransmission">
    <type>transmission_interface/SimpleTransmission</type>
    <actuator name="throwing_motor">
      <mechanicalReduction>1</mechanicalReduction>
    </actuator>
    <joint name="throwing">
      <hardwareInterface>hardware_interface/VelocityJointInterface</hardwareInterface>
    </joint>
  </transmission>

  <gazebo>
    <plugin name="gazebo_ros_control" filename="libgazebo_ros_control.so">
      <robotNamespace>/catapult</robotNamespace>
      <robotSimType>gazebo_ros_control/DefaultRobotHWSim</robotSimType>
      <legacyModeNS>true</legacyModeNS>
    </plugin>
  </gazebo>
</robot>
